Warning: untrusted X11 forwarding setup failed: xauth key data not generated
Traceback (most recent call last):
  File "download_from_flywheel.py", line 136, in <module>
    os.makedirs(split_path(pjoin(scanidpath,download_pair[1].replace('*',file['name'])))[0],exist_ok=True)
  File "/oak/stanford/groups/menon/software/python/miniconda2/envs/fw/lib/python3.6/os.py", line 210, in makedirs
    makedirs(head, mode, exist_ok)
  File "/oak/stanford/groups/menon/software/python/miniconda2/envs/fw/lib/python3.6/os.py", line 210, in makedirs
    makedirs(head, mode, exist_ok)
  File "/oak/stanford/groups/menon/software/python/miniconda2/envs/fw/lib/python3.6/os.py", line 210, in makedirs
    makedirs(head, mode, exist_ok)
  [Previous line repeated 1 more times]
  File "/oak/stanford/groups/menon/software/python/miniconda2/envs/fw/lib/python3.6/os.py", line 220, in makedirs
    mkdir(name, mode)
PermissionError: [Errno 13] Permission denied: '/oak/stanford/groups/menon/rawdata/scsnl/8098'
